Workbook

Sheet Summary
A1: LAGUNA RIDGE ACQUISITION
A2: Financial Model Summary
A3: CONFIDENTIAL
A5: KEY METRICS
A6: Total Capital Required | B6: =Capital!B36 -> 190 | C6: $M
A7: Annual Operating Cost | B7: =Operating!B21 -> 0 | C7: $M
A8: Required Endowment (5% draw) | B8: =Operating!B21/0.05 -> 0 | C8: $M
A9: Total Raise (incl. endowment) | B9: =B6+B8 -> 190 | C9: $M
A11: Acquisition Cost (Base Case) | B11: =Scenarios!C8 -> 0 | C11: $M
A12: Building Renovation | B12: =Capital!B14 -> 20 | C12: $M
A13: Display Infrastructure | B13: =Capital!B24 -> 15 | C13: $M
A17: FUNDING STRATEGY
A18: Foundation Grants | B18: =Funding!B7 -> 60 | C18: $M
A19: Corporate Partnership | B19: =Funding!B8 -> 125 | C19: $M
A20: Government Grants | B20: =Funding!B9 -> 200 | C20: $M
A21: Impact Investment | B21: =Funding!B10 -> 0 | C21: $M
A22: Operating Endowment | B22: =Funding!B11 -> 860 | C22: $M
A23: TOTAL | B23: =SUM(B18:B22) -> 1245 | C23: $M

Sheet Scenarios
A1: ACQUISITION SCENARIOS
A3: Scenario | B3: Acquisition Cost | C3: Probability | D3: Weighted Cost | E3: Notes
A4: Public Benefit Conveyance | B4: 0 | C4: 0.3 | D4: =B4*C4 -> 0 | E4: Best case - requires 501(c)(3)
A5: Negotiated Below-Market | B5: 35 | C5: 0.35 | D5: =B5*C5 -> 12.25 | E5: Public benefit discount
A6: Negotiated Market Rate | B6: 100 | C6: 0.2 | D6: =B6*C6 -> 20 | E6: Based on failed auctions
A7: Auction Win | B7: 180 | C7: 0.15 | D7: =B7*C7 -> 27 | E7: Would need to outbid Hoag
A8: Expected Value | D8: =SUM(D4:D7) -> 59.25
A10: BASE CASE ASSUMPTION
A11: Using Scenario: | B11: Negotiated Below-Market
A12: Acquisition Cost ($M): | B12: 50

Sheet Capital
A1: CAPITAL BUDGET
A3: Category | B3: Low ($M) | C3: High ($M) | D3: Notes
A4: ACQUISITION
A5: Property Purchase | B5: 0 | C5: 50 | D5: Per Scenarios sheet
A6: Due Diligence | B6: 0.5 | C6: 1 | D6: Environmental, structural, legal
A7: Legal/Transaction | B7: 1 | C7: 2 | D7: Attorneys, closing costs
A8: Acquisition Subtotal | B8: =SUM(B5:B7) -> 1.5 | C8: =SUM(C5:C7) -> 53
A10: REMEDIATION & SYSTEMS
A11: Asbestos Abatement | B11: 20 | C11: 40 | D11: Depends on extent
A12: HVAC Replacement | B12: 30 | C12: 50 | D12: Full system
A13: Electrical Upgrade | B13: 15 | C13: 25
A14: Fire/Life Safety | B14: 20 | C14: 30 | D14: Code compliance
A15: Plumbing | B15: 10 | C15: 15
A16: Elevators | B16: 10 | C16: 15 | D16: Modernization
A17: Roof | B17: 15 | C17: 20
A18: ADA Compliance | B18: 10 | C18: 15
A19: Structural Repairs | B19: 10 | C19: 20 | D19: If needed
A20: Remediation Subtotal | B20: =SUM(B11:B19) -> 140 | C20: =SUM(C11:C19) -> 230
A22: INTERIOR BUILD-OUT
A23: Production Facilities | B23: 20 | C23: 35 | D23: Video, broadcast
A24: Office/Operations | B24: 15 | C24: 25
A25: Visitor Center | B25: 10 | C25: 20 | D25: Atrium, exhibits
A26: Technology Infrastructure | B26: 15 | C26: 25 | D26: Network, servers
A27: Furniture/Equipment | B27: 10 | C27: 15
A28: Interior Subtotal | B28: =SUM(B23:B27) -> 70 | C28: =SUM(C23:C27) -> 120
A30: DISPLAY INFRASTRUCTURE
A31: LED Mesh/Panels | B31: 120 | C31: 250 | D31: 13 terraces
A32: Structural Mounting | B32: 20 | C32: 40 | D32: Engineering
A33: Power Infrastructure | B33: 15 | C33: 30 | D33: Significant load
A34: Control Systems | B34: 10 | C34: 20 | D34: Software, hardware
A35: Installation | B35: 25 | C35: 50 | D35: Complex job
A36: Display Subtotal | B36: =SUM(B31:B35) -> 190 | C36: =SUM(C31:C35) -> 390
A38: SITE & PARKING
A39: Landscaping Restoration | B39: 5 | C39: 10
A40: Parking Repairs | B40: 3 | C40: 5
A41: Security Infrastructure | B41: 2 | C41: 5
A42: Site Subtotal | B42: =SUM(B39:B41) -> 10 | C42: =SUM(C39:C41) -> 20
A44: TOTALS
A45: Hard Costs Subtotal | B45: =B8+B20+B28+B36+B42 -> 411.5 | C45: =C8+C20+C28+C36+C42 -> 813
A46: Contingency (20%) | B46: =B45*0.2 -> 82.3 | C46: =C45*0.2 -> 162.6
...

Sheet Operating
A1: ANNUAL OPERATING BUDGET
A3: Category | B3: Low ($M) | C3: High ($M) | D3: Notes
A4: Utilities | B4: 4 | C4: 6 | D4: Display infrastructure is power-hungry
A5: Maintenance | B5: 3 | C5: 4 | D5: Building + displays
A6: Security | B6: 1.5 | C6: 2 | D6: 24/7 coverage
A7: Insurance | B7: 2 | C7: 3
A8: Property Tax | B8: 0 | C8: 3 | D8: Depends on exemptions
A9: Content Production | B9: 5 | C9: 8 | D9: Ongoing lessons
A10: Technology/IT | B10: 2 | C10: 3
A11: Staff - Facility | B11: 4 | C11: 5 | D11: 50-75 FTE
A12: Staff - Content/Ops | B12: 6 | C12: 8 | D12: 75-100 FTE
A14: TOTAL ANNUAL OPERATING | B14: =SUM(B4:B12) -> 27.5 | C14: =SUM(C4:C12) -> 42
A17: ENDOWMENT CALCULATION
A18: Target Annual Draw Rate | B18: 0.05
A19: Required Endowment (based on mid-point operating) | B19: =(B14+C14)/2/B18 -> 695

Sheet Funding
A1: FUNDING SOURCES
A3: Source | B3: Target ($M) | C3: Status | D3: Notes
A4: CAPITAL FUNDING
A5: Foundation Grants | B5: 350 | C5: Not started | D5: Long-term, patient capital
A6: Corporate Partnership | B6: 125 | C6: Not started | D6: Display technology partner
A7: Government Grants | B7: 60 | C7: Not started | D7: Education, workforce
A8: Impact Investment | B8: 125 | C8: Not started | D8: Mission-aligned investors
A9: Operating Endowment | B9: 200 | C9: Not started | D9: Multi-year campaign
A11: TOTAL FUNDING TARGET | B11: =SUM(B5:B9) -> 860
A14: OPERATING FUNDING (ANNUAL)
A15: Foundation Operating Grants | B15: 12 | C15: Recurring | D15: Multi-year commitments
A16: Corporate Sponsorship | B16: 7 | C16: Recurring | D16: Display time, naming
A17: Earned Revenue | B17: 4 | C17: Recurring | D17: Events, tours, licensing
A18: Government Contracts | B18: 4 | C18: Recurring | D18: Educational services
A19: Endowment Draw | B19: 8 | C19: Recurring | D19: From $200M endowment @ 4%
A21: TOTAL OPERATING FUNDING | B21: =SUM(B15:B19) -> 35

Sheet Timeline
A1: PROJECT TIMELINE
A3: Milestone | B3: Target | C3: Dependencies
A4: Phase 0: Preparation
A5: Engage attorney | B5: Week 1
A6: Form LLCs | B6: Week 2-3 | C6: Attorney
A7: Intelligence gathering | B7: Week 2-4
A8: FOIA request submitted | B8: Week 2
A10: Phase 1: Quiet Outreach
A11: GSA initial contact | B11: Month 2 | C11: Entities formed
A12: Nonprofit structure decision | B12: Month 2 | C12: Legal advice
A13: Foundation research complete | B13: Month 3
A15: Phase 2: Engagement
A16: GSA letter of interest | B16: Month 4 | C16: GSA receptive
A17: Foundation meetings begin | B17: Month 4 | C17: Materials ready
A18: Due diligence (if GSA engaged) | B18: Month 5-6 | C18: GSA engagement
A20: Phase 3: Commitment
A21: GSA terms finalized | B21: Month 8 | C21: Due diligence complete
A22: Lead foundation commitment | B22: Month 9 | C22: GSA path clear
A23: Transaction close | B23: Month 12 | C23: Funding committed
A24: Public announcement | B24: Month 12 | C24: Deal closed
A26: Phase 4: Transformation
A27: Remediation begins | B27: Month 15 | C27: Ownership
A28: Display design finalized | B28: Month 18
A29: Core systems online | B29: Month 24
A30: Display installation | B30: Month 30
A31: Soft opening | B31: Month 34
A32: Grand opening | B32: Month 36
